[2024-01-31T15:12:14.830+0000] {taskinstance.py:1956} INFO - Dependencies all met for dep_context=non-requeueable deps ti=<TaskInstance: cvd_automation_pipeline.enrich_nuclei_data_task manual__2024-01-31T15:12:06.456390+00:00 [queued]>
[2024-01-31T15:12:14.838+0000] {taskinstance.py:1956} INFO - Dependencies all met for dep_context=requeueable deps ti=<TaskInstance: cvd_automation_pipeline.enrich_nuclei_data_task manual__2024-01-31T15:12:06.456390+00:00 [queued]>
[2024-01-31T15:12:14.839+0000] {taskinstance.py:2170} INFO - Starting attempt 1 of 1
[2024-01-31T15:12:14.852+0000] {taskinstance.py:2191} INFO - Executing <Task(PythonOperator): enrich_nuclei_data_task> on 2024-01-31 15:12:06.456390+00:00
[2024-01-31T15:12:14.856+0000] {standard_task_runner.py:60} INFO - Started process 14354 to run task
[2024-01-31T15:12:14.858+0000] {standard_task_runner.py:87} INFO - Running: ['***', 'tasks', 'run', 'cvd_automation_pipeline', 'enrich_nuclei_data_task', 'manual__2024-01-31T15:12:06.456390+00:00', '--job-id', '28', '--raw', '--subdir', 'DAGS_FOLDER/cvd_pipeline_1.py', '--cfg-path', '/tmp/tmppz7cityw']
[2024-01-31T15:12:14.860+0000] {standard_task_runner.py:88} INFO - Job 28: Subtask enrich_nuclei_data_task
[2024-01-31T15:12:14.896+0000] {task_command.py:423} INFO - Running <TaskInstance: cvd_automation_pipeline.enrich_nuclei_data_task manual__2024-01-31T15:12:06.456390+00:00 [running]> on host 8d8bbdf320cd
[2024-01-31T15:12:14.966+0000] {taskinstance.py:2480} INFO - Exporting env vars: AIRFLOW_CTX_DAG_OWNER='***' AIRFLOW_CTX_DAG_ID='cvd_automation_pipeline' AIRFLOW_CTX_TASK_ID='enrich_nuclei_data_task' AIRFLOW_CTX_EXECUTION_DATE='2024-01-31T15:12:06.456390+00:00' AIRFLOW_CTX_TRY_NUMBER='1' AIRFLOW_CTX_DAG_RUN_ID='manual__2024-01-31T15:12:06.456390+00:00'
[2024-01-31T15:12:15.640+0000] {taskinstance.py:2698} ERROR - Task failed with exception
Traceback (most recent call last):
  File "/home/airflow/.local/lib/python3.8/site-packages/airflow/models/taskinstance.py", line 433, in _execute_task
    result = execute_callable(context=context, **execute_callable_kwargs)
  File "/home/airflow/.local/lib/python3.8/site-packages/airflow/operators/python.py", line 199, in execute
    return_value = self.execute_callable()
  File "/home/airflow/.local/lib/python3.8/site-packages/airflow/operators/python.py", line 216, in execute_callable
    return self.python_callable(*self.op_args, **self.op_kwargs)
  File "/opt/airflow/dags/cvd_pipeline_1.py", line 148, in enrich_nuclei_data
    subprocess.run(cmd, shell=True, check=True)
  File "/usr/local/lib/python3.8/subprocess.py", line 516, in run
    raise CalledProcessError(retcode, process.args,
subprocess.CalledProcessError: Command 'cd /opt/airflow/nuclei-parse-enrich && go run cmd/main.go -i ../data/2024-01-31-nuclei-results.json -o ../data/enriched_nuclei_results/output.json' returned non-zero exit status 1.
[2024-01-31T15:12:15.652+0000] {taskinstance.py:1138} INFO - Marking task as FAILED. dag_id=cvd_automation_pipeline, task_id=enrich_nuclei_data_task, execution_date=20240131T151206, start_date=20240131T151214, end_date=20240131T151215
[2024-01-31T15:12:15.666+0000] {standard_task_runner.py:107} ERROR - Failed to execute job 28 for task enrich_nuclei_data_task (Command 'cd /opt/airflow/nuclei-parse-enrich && go run cmd/main.go -i ../data/2024-01-31-nuclei-results.json -o ../data/enriched_nuclei_results/output.json' returned non-zero exit status 1.; 14354)
[2024-01-31T15:12:15.673+0000] {local_task_job_runner.py:234} INFO - Task exited with return code 1
[2024-01-31T15:12:15.688+0000] {taskinstance.py:3280} INFO - 0 downstream tasks scheduled from follow-on schedule check
