[2024-01-30T23:25:35.744+0000] {taskinstance.py:1956} INFO - Dependencies all met for dep_context=non-requeueable deps ti=<TaskInstance: vulnerability_email_notification.process_vulnerability_data manual__2024-01-30T23:25:34.680483+00:00 [queued]>
[2024-01-30T23:25:35.758+0000] {taskinstance.py:1956} INFO - Dependencies all met for dep_context=requeueable deps ti=<TaskInstance: vulnerability_email_notification.process_vulnerability_data manual__2024-01-30T23:25:34.680483+00:00 [queued]>
[2024-01-30T23:25:35.759+0000] {taskinstance.py:2170} INFO - Starting attempt 1 of 2
[2024-01-30T23:25:35.782+0000] {taskinstance.py:2191} INFO - Executing <Task(PythonOperator): process_vulnerability_data> on 2024-01-30 23:25:34.680483+00:00
[2024-01-30T23:25:35.789+0000] {standard_task_runner.py:60} INFO - Started process 6093 to run task
[2024-01-30T23:25:35.793+0000] {standard_task_runner.py:87} INFO - Running: ['***', 'tasks', 'run', 'vulnerability_email_notification', 'process_vulnerability_data', 'manual__2024-01-30T23:25:34.680483+00:00', '--job-id', '15', '--raw', '--subdir', 'DAGS_FOLDER/cvd_mail_and_reschedule.py', '--cfg-path', '/tmp/tmpbsw8v1ut']
[2024-01-30T23:25:35.796+0000] {standard_task_runner.py:88} INFO - Job 15: Subtask process_vulnerability_data
[2024-01-30T23:25:35.858+0000] {task_command.py:423} INFO - Running <TaskInstance: vulnerability_email_notification.process_vulnerability_data manual__2024-01-30T23:25:34.680483+00:00 [running]> on host 8d8bbdf320cd
[2024-01-30T23:25:35.968+0000] {taskinstance.py:2480} INFO - Exporting env vars: AIRFLOW_CTX_DAG_OWNER='***' AIRFLOW_CTX_DAG_ID='vulnerability_email_notification' AIRFLOW_CTX_TASK_ID='process_vulnerability_data' AIRFLOW_CTX_EXECUTION_DATE='2024-01-30T23:25:34.680483+00:00' AIRFLOW_CTX_TRY_NUMBER='1' AIRFLOW_CTX_DAG_RUN_ID='manual__2024-01-30T23:25:34.680483+00:00'
[2024-01-30T23:25:35.971+0000] {taskinstance.py:2698} ERROR - Task failed with exception
Traceback (most recent call last):
  File "/home/airflow/.local/lib/python3.8/site-packages/airflow/models/taskinstance.py", line 433, in _execute_task
    result = execute_callable(context=context, **execute_callable_kwargs)
  File "/home/airflow/.local/lib/python3.8/site-packages/airflow/operators/python.py", line 199, in execute
    return_value = self.execute_callable()
  File "/home/airflow/.local/lib/python3.8/site-packages/airflow/operators/python.py", line 216, in execute_callable
    return self.python_callable(*self.op_args, **self.op_kwargs)
  File "/opt/airflow/dags/cvd_mail_and_reschedule.py", line 69, in process_vulnerability_data
    server = smtplib.SMTP(smtp_server, smtp_port)
  File "/usr/local/lib/python3.8/smtplib.py", line 255, in __init__
    (code, msg) = self.connect(host, port)
  File "/usr/local/lib/python3.8/smtplib.py", line 339, in connect
    self.sock = self._get_socket(host, port, self.timeout)
  File "/usr/local/lib/python3.8/smtplib.py", line 310, in _get_socket
    return socket.create_connection((host, port), timeout,
  File "/usr/local/lib/python3.8/socket.py", line 808, in create_connection
    raise err
  File "/usr/local/lib/python3.8/socket.py", line 796, in create_connection
    sock.connect(sa)
OSError: [Errno 99] Cannot assign requested address
[2024-01-30T23:25:35.986+0000] {taskinstance.py:1138} INFO - Marking task as UP_FOR_RETRY. dag_id=vulnerability_email_notification, task_id=process_vulnerability_data, execution_date=20240130T232534, start_date=20240130T232535, end_date=20240130T232535
[2024-01-30T23:25:36.002+0000] {standard_task_runner.py:107} ERROR - Failed to execute job 15 for task process_vulnerability_data ([Errno 99] Cannot assign requested address; 6093)
[2024-01-30T23:25:36.046+0000] {local_task_job_runner.py:234} INFO - Task exited with return code 1
[2024-01-30T23:25:36.068+0000] {taskinstance.py:3280} INFO - 0 downstream tasks scheduled from follow-on schedule check
