[2024-01-31T15:12:13.416+0000] {taskinstance.py:1956} INFO - Dependencies all met for dep_context=non-requeueable deps ti=<TaskInstance: cvd_automation_pipeline.run_nuclei_scan_task manual__2024-01-31T15:12:06.456390+00:00 [queued]>
[2024-01-31T15:12:13.425+0000] {taskinstance.py:1956} INFO - Dependencies all met for dep_context=requeueable deps ti=<TaskInstance: cvd_automation_pipeline.run_nuclei_scan_task manual__2024-01-31T15:12:06.456390+00:00 [queued]>
[2024-01-31T15:12:13.425+0000] {taskinstance.py:2170} INFO - Starting attempt 1 of 1
[2024-01-31T15:12:13.438+0000] {taskinstance.py:2191} INFO - Executing <Task(PythonOperator): run_nuclei_scan_task> on 2024-01-31 15:12:06.456390+00:00
[2024-01-31T15:12:13.442+0000] {standard_task_runner.py:60} INFO - Started process 14333 to run task
[2024-01-31T15:12:13.444+0000] {standard_task_runner.py:87} INFO - Running: ['***', 'tasks', 'run', 'cvd_automation_pipeline', 'run_nuclei_scan_task', 'manual__2024-01-31T15:12:06.456390+00:00', '--job-id', '27', '--raw', '--subdir', 'DAGS_FOLDER/cvd_pipeline_1.py', '--cfg-path', '/tmp/tmp6sc0z6oa']
[2024-01-31T15:12:13.446+0000] {standard_task_runner.py:88} INFO - Job 27: Subtask run_nuclei_scan_task
[2024-01-31T15:12:13.487+0000] {task_command.py:423} INFO - Running <TaskInstance: cvd_automation_pipeline.run_nuclei_scan_task manual__2024-01-31T15:12:06.456390+00:00 [running]> on host 8d8bbdf320cd
[2024-01-31T15:12:13.566+0000] {taskinstance.py:2480} INFO - Exporting env vars: AIRFLOW_CTX_DAG_OWNER='***' AIRFLOW_CTX_DAG_ID='cvd_automation_pipeline' AIRFLOW_CTX_TASK_ID='run_nuclei_scan_task' AIRFLOW_CTX_EXECUTION_DATE='2024-01-31T15:12:06.456390+00:00' AIRFLOW_CTX_TRY_NUMBER='1' AIRFLOW_CTX_DAG_RUN_ID='manual__2024-01-31T15:12:06.456390+00:00'
[2024-01-31T15:12:14.441+0000] {logging_mixin.py:188} INFO - An error occurred while running Nuclei command: Command 'nuclei -H 'User-Agent: DIVD-2023-00020' -t /opt/***/data/fingerprint_data.yaml -l data/DIVD-2024-XXXX/2024-01-31-shodan-results.csv -retries 2 -timeout 6 -output data/DIVD-2024-XXXX/2024-01-31-nuclei-results.json -j' returned non-zero exit status 1.
[2024-01-31T15:12:14.442+0000] {logging_mixin.py:188} INFO - None
[2024-01-31T15:12:14.443+0000] {logging_mixin.py:188} INFO - An error occurred while reading the file: [Errno 2] No such file or directory: 'data/DIVD-2024-XXXX/2024-01-31-nuclei-results.json'
[2024-01-31T15:12:14.443+0000] {logging_mixin.py:188} INFO - Nuclei scan completed.
[2024-01-31T15:12:14.443+0000] {python.py:201} INFO - Done. Returned value was: None
[2024-01-31T15:12:14.453+0000] {taskinstance.py:1138} INFO - Marking task as SUCCESS. dag_id=cvd_automation_pipeline, task_id=run_nuclei_scan_task, execution_date=20240131T151206, start_date=20240131T151213, end_date=20240131T151214
[2024-01-31T15:12:14.500+0000] {local_task_job_runner.py:234} INFO - Task exited with return code 0
[2024-01-31T15:12:14.520+0000] {taskinstance.py:3280} INFO - 1 downstream tasks scheduled from follow-on schedule check
