[2024-01-30T18:57:14.974+0000] {taskinstance.py:1956} INFO - Dependencies all met for dep_context=non-requeueable deps ti=<TaskInstance: cvd_automation_pipeline.enrich_nuclei_data_task manual__2024-01-30T18:57:07.397759+00:00 [queued]>
[2024-01-30T18:57:14.982+0000] {taskinstance.py:1956} INFO - Dependencies all met for dep_context=requeueable deps ti=<TaskInstance: cvd_automation_pipeline.enrich_nuclei_data_task manual__2024-01-30T18:57:07.397759+00:00 [queued]>
[2024-01-30T18:57:14.983+0000] {taskinstance.py:2170} INFO - Starting attempt 1 of 1
[2024-01-30T18:57:14.995+0000] {taskinstance.py:2191} INFO - Executing <Task(PythonOperator): enrich_nuclei_data_task> on 2024-01-30 18:57:07.397759+00:00
[2024-01-30T18:57:14.999+0000] {standard_task_runner.py:60} INFO - Started process 1966 to run task
[2024-01-30T18:57:15.001+0000] {standard_task_runner.py:87} INFO - Running: ['***', 'tasks', 'run', 'cvd_automation_pipeline', 'enrich_nuclei_data_task', 'manual__2024-01-30T18:57:07.397759+00:00', '--job-id', '14', '--raw', '--subdir', 'DAGS_FOLDER/cvd_pipeline_1.py', '--cfg-path', '/tmp/tmp36l558sr']
[2024-01-30T18:57:15.003+0000] {standard_task_runner.py:88} INFO - Job 14: Subtask enrich_nuclei_data_task
[2024-01-30T18:57:15.038+0000] {task_command.py:423} INFO - Running <TaskInstance: cvd_automation_pipeline.enrich_nuclei_data_task manual__2024-01-30T18:57:07.397759+00:00 [running]> on host 8d8bbdf320cd
[2024-01-30T18:57:15.101+0000] {taskinstance.py:2480} INFO - Exporting env vars: AIRFLOW_CTX_DAG_OWNER='***' AIRFLOW_CTX_DAG_ID='cvd_automation_pipeline' AIRFLOW_CTX_TASK_ID='enrich_nuclei_data_task' AIRFLOW_CTX_EXECUTION_DATE='2024-01-30T18:57:07.397759+00:00' AIRFLOW_CTX_TRY_NUMBER='1' AIRFLOW_CTX_DAG_RUN_ID='manual__2024-01-30T18:57:07.397759+00:00'
[2024-01-30T18:57:38.125+0000] {logging_mixin.py:188} INFO - Error retrieving security.txt for 124.222.233.238: HTTPSConnectionPool(host='124.222.233.238', port=443): Max retries exceeded with url: /.well-known/security.txt (Caused by SSLError(SSLZeroReturnError(6, 'TLS/SSL connection has been closed (EOF) (_ssl.c:1131)')))
[2024-01-30T18:57:38.360+0000] {logging_mixin.py:188} INFO - Error retrieving security.txt for 15.157.71.1: HTTPSConnectionPool(host='15.157.71.1', port=443): Max retries exceeded with url: /.well-known/security.txt (Caused by SSLError(SSLCertVerificationError(1, '[SSL: CERTIFICATE_VERIFY_FAILED] certificate verify failed: self-signed certificate (_ssl.c:1131)')))
[2024-01-30T18:57:38.583+0000] {logging_mixin.py:188} INFO - Error retrieving security.txt for 3.84.44.179: HTTPSConnectionPool(host='3.84.44.179', port=443): Max retries exceeded with url: /.well-known/security.txt (Caused by SSLError(SSLCertVerificationError(1, '[SSL: CERTIFICATE_VERIFY_FAILED] certificate verify failed: self-signed certificate (_ssl.c:1131)')))
[2024-01-30T18:57:59.640+0000] {logging_mixin.py:188} INFO - Error retrieving security.txt for 43.192.116.82: HTTPSConnectionPool(host='43.192.116.82', port=443): Max retries exceeded with url: /.well-known/security.txt (Caused by SSLError(SSLZeroReturnError(6, 'TLS/SSL connection has been closed (EOF) (_ssl.c:1131)')))
[2024-01-30T18:57:59.877+0000] {logging_mixin.py:188} INFO - Error retrieving security.txt for 44.203.250.21: HTTPSConnectionPool(host='44.203.250.21', port=443): Max retries exceeded with url: /.well-known/security.txt (Caused by SSLError(SSLCertVerificationError(1, '[SSL: CERTIFICATE_VERIFY_FAILED] certificate verify failed: self-signed certificate (_ssl.c:1131)')))
[2024-01-30T18:57:59.960+0000] {logging_mixin.py:188} INFO - Error retrieving security.txt for 51.21.131.99: HTTPSConnectionPool(host='51.21.131.99', port=443): Max retries exceeded with url: /.well-known/security.txt (Caused by SSLError(SSLCertVerificationError(1, '[SSL: CERTIFICATE_VERIFY_FAILED] certificate verify failed: self-signed certificate (_ssl.c:1131)')))
[2024-01-30T18:58:00.178+0000] {logging_mixin.py:188} INFO - Error retrieving security.txt for 52.23.211.219: HTTPSConnectionPool(host='52.23.211.219', port=443): Max retries exceeded with url: /.well-known/security.txt (Caused by SSLError(SSLCertVerificationError(1, '[SSL: CERTIFICATE_VERIFY_FAILED] certificate verify failed: self-signed certificate (_ssl.c:1131)')))
[2024-01-30T18:58:00.393+0000] {logging_mixin.py:188} INFO - Error retrieving security.txt for 54.224.146.28: HTTPSConnectionPool(host='54.224.146.28', port=443): Max retries exceeded with url: /.well-known/security.txt (Caused by SSLError(SSLCertVerificationError(1, '[SSL: CERTIFICATE_VERIFY_FAILED] certificate verify failed: self-signed certificate (_ssl.c:1131)')))
[2024-01-30T18:58:00.787+0000] {logging_mixin.py:188} INFO - Error retrieving security.txt for 65.1.100.235: HTTPSConnectionPool(host='65.1.100.235', port=443): Max retries exceeded with url: /.well-known/security.txt (Caused by SSLError(SSLCertVerificationError(1, '[SSL: CERTIFICATE_VERIFY_FAILED] certificate verify failed: self-signed certificate (_ssl.c:1131)')))
[2024-01-30T18:58:21.847+0000] {logging_mixin.py:188} INFO - Error retrieving security.txt for 68.79.11.55: HTTPSConnectionPool(host='68.79.11.55', port=443): Max retries exceeded with url: /.well-known/security.txt (Caused by SSLError(SSLZeroReturnError(6, 'TLS/SSL connection has been closed (EOF) (_ssl.c:1131)')))
[2024-01-30T18:58:21.852+0000] {logging_mixin.py:188} INFO - Enrichment step completed.
[2024-01-30T18:58:21.853+0000] {python.py:201} INFO - Done. Returned value was: None
[2024-01-30T18:58:21.862+0000] {taskinstance.py:1138} INFO - Marking task as SUCCESS. dag_id=cvd_automation_pipeline, task_id=enrich_nuclei_data_task, execution_date=20240130T185707, start_date=20240130T185714, end_date=20240130T185821
[2024-01-30T18:58:21.894+0000] {local_task_job_runner.py:234} INFO - Task exited with return code 0
[2024-01-30T18:58:21.906+0000] {taskinstance.py:3280} INFO - 0 downstream tasks scheduled from follow-on schedule check
