[2024-01-31T15:35:06.189+0000] {taskinstance.py:1956} INFO - Dependencies all met for dep_context=non-requeueable deps ti=<TaskInstance: cvd_automation_pipeline.enrich_nuclei_data_task manual__2024-01-31T15:34:47.692492+00:00 [queued]>
[2024-01-31T15:35:06.197+0000] {taskinstance.py:1956} INFO - Dependencies all met for dep_context=requeueable deps ti=<TaskInstance: cvd_automation_pipeline.enrich_nuclei_data_task manual__2024-01-31T15:34:47.692492+00:00 [queued]>
[2024-01-31T15:35:06.197+0000] {taskinstance.py:2170} INFO - Starting attempt 1 of 1
[2024-01-31T15:35:06.213+0000] {taskinstance.py:2191} INFO - Executing <Task(PythonOperator): enrich_nuclei_data_task> on 2024-01-31 15:34:47.692492+00:00
[2024-01-31T15:35:06.217+0000] {standard_task_runner.py:60} INFO - Started process 16655 to run task
[2024-01-31T15:35:06.219+0000] {standard_task_runner.py:87} INFO - Running: ['***', 'tasks', 'run', 'cvd_automation_pipeline', 'enrich_nuclei_data_task', 'manual__2024-01-31T15:34:47.692492+00:00', '--job-id', '46', '--raw', '--subdir', 'DAGS_FOLDER/cvd_pipeline_1.py', '--cfg-path', '/tmp/tmp_fjbfuqr']
[2024-01-31T15:35:06.221+0000] {standard_task_runner.py:88} INFO - Job 46: Subtask enrich_nuclei_data_task
[2024-01-31T15:35:06.261+0000] {task_command.py:423} INFO - Running <TaskInstance: cvd_automation_pipeline.enrich_nuclei_data_task manual__2024-01-31T15:34:47.692492+00:00 [running]> on host 8d8bbdf320cd
[2024-01-31T15:35:06.330+0000] {taskinstance.py:2480} INFO - Exporting env vars: AIRFLOW_CTX_DAG_OWNER='***' AIRFLOW_CTX_DAG_ID='cvd_automation_pipeline' AIRFLOW_CTX_TASK_ID='enrich_nuclei_data_task' AIRFLOW_CTX_EXECUTION_DATE='2024-01-31T15:34:47.692492+00:00' AIRFLOW_CTX_TRY_NUMBER='1' AIRFLOW_CTX_DAG_RUN_ID='manual__2024-01-31T15:34:47.692492+00:00'
[2024-01-31T15:35:08.489+0000] {logging_mixin.py:188} INFO - Error retrieving security.txt for 13.53.124.43: HTTPSConnectionPool(host='13.53.124.43', port=443): Max retries exceeded with url: /.well-known/security.txt (Caused by SSLError(SSLCertVerificationError(1, '[SSL: CERTIFICATE_VERIFY_FAILED] certificate verify failed: self-signed certificate (_ssl.c:1131)')))
[2024-01-31T15:35:08.961+0000] {logging_mixin.py:188} INFO - Error retrieving security.txt for 18.228.238.231: HTTPSConnectionPool(host='18.228.238.231', port=443): Max retries exceeded with url: /.well-known/security.txt (Caused by SSLError(SSLCertVerificationError(1, '[SSL: CERTIFICATE_VERIFY_FAILED] certificate verify failed: self-signed certificate (_ssl.c:1131)')))
[2024-01-31T15:35:09.017+0000] {logging_mixin.py:188} INFO - Error retrieving security.txt for 3.8.19.26: HTTPSConnectionPool(host='3.8.19.26', port=443): Max retries exceeded with url: /.well-known/security.txt (Caused by SSLError(SSLCertVerificationError(1, '[SSL: CERTIFICATE_VERIFY_FAILED] certificate verify failed: self-signed certificate (_ssl.c:1131)')))
[2024-01-31T15:35:09.442+0000] {logging_mixin.py:188} INFO - Error retrieving security.txt for 54.191.55.233: HTTPSConnectionPool(host='54.191.55.233', port=443): Max retries exceeded with url: /.well-known/security.txt (Caused by SSLError(SSLCertVerificationError(1, '[SSL: CERTIFICATE_VERIFY_FAILED] certificate verify failed: self-signed certificate (_ssl.c:1131)')))
[2024-01-31T15:35:09.447+0000] {logging_mixin.py:188} INFO - Enrichment step completed.
[2024-01-31T15:35:09.447+0000] {python.py:201} INFO - Done. Returned value was: None
[2024-01-31T15:35:09.456+0000] {taskinstance.py:1138} INFO - Marking task as SUCCESS. dag_id=cvd_automation_pipeline, task_id=enrich_nuclei_data_task, execution_date=20240131T153447, start_date=20240131T153506, end_date=20240131T153509
[2024-01-31T15:35:09.487+0000] {local_task_job_runner.py:234} INFO - Task exited with return code 0
[2024-01-31T15:35:09.502+0000] {taskinstance.py:3280} INFO - 0 downstream tasks scheduled from follow-on schedule check
