[2024-01-31T15:28:50.187+0000] {taskinstance.py:1956} INFO - Dependencies all met for dep_context=non-requeueable deps ti=<TaskInstance: cvd_automation_pipeline.enrich_nuclei_data_task manual__2024-01-31T15:28:28.101563+00:00 [queued]>
[2024-01-31T15:28:50.195+0000] {taskinstance.py:1956} INFO - Dependencies all met for dep_context=requeueable deps ti=<TaskInstance: cvd_automation_pipeline.enrich_nuclei_data_task manual__2024-01-31T15:28:28.101563+00:00 [queued]>
[2024-01-31T15:28:50.195+0000] {taskinstance.py:2170} INFO - Starting attempt 1 of 1
[2024-01-31T15:28:50.207+0000] {taskinstance.py:2191} INFO - Executing <Task(PythonOperator): enrich_nuclei_data_task> on 2024-01-31 15:28:28.101563+00:00
[2024-01-31T15:28:50.211+0000] {standard_task_runner.py:60} INFO - Started process 15768 to run task
[2024-01-31T15:28:50.213+0000] {standard_task_runner.py:87} INFO - Running: ['***', 'tasks', 'run', 'cvd_automation_pipeline', 'enrich_nuclei_data_task', 'manual__2024-01-31T15:28:28.101563+00:00', '--job-id', '37', '--raw', '--subdir', 'DAGS_FOLDER/cvd_pipeline_1.py', '--cfg-path', '/tmp/tmp1y6cwadn']
[2024-01-31T15:28:50.214+0000] {standard_task_runner.py:88} INFO - Job 37: Subtask enrich_nuclei_data_task
[2024-01-31T15:28:50.247+0000] {task_command.py:423} INFO - Running <TaskInstance: cvd_automation_pipeline.enrich_nuclei_data_task manual__2024-01-31T15:28:28.101563+00:00 [running]> on host 8d8bbdf320cd
[2024-01-31T15:28:50.309+0000] {taskinstance.py:2480} INFO - Exporting env vars: AIRFLOW_CTX_DAG_OWNER='***' AIRFLOW_CTX_DAG_ID='cvd_automation_pipeline' AIRFLOW_CTX_TASK_ID='enrich_nuclei_data_task' AIRFLOW_CTX_EXECUTION_DATE='2024-01-31T15:28:28.101563+00:00' AIRFLOW_CTX_TRY_NUMBER='1' AIRFLOW_CTX_DAG_RUN_ID='manual__2024-01-31T15:28:28.101563+00:00'
[2024-01-31T15:28:52.679+0000] {logging_mixin.py:188} INFO - Error retrieving security.txt for 100.26.189.36: HTTPSConnectionPool(host='100.26.189.36', port=443): Max retries exceeded with url: /.well-known/security.txt (Caused by SSLError(SSLCertVerificationError(1, '[SSL: CERTIFICATE_VERIFY_FAILED] certificate verify failed: self-signed certificate (_ssl.c:1131)')))
[2024-01-31T15:28:53.024+0000] {logging_mixin.py:188} INFO - Error retrieving security.txt for 13.244.157.79: HTTPSConnectionPool(host='13.244.157.79', port=443): Max retries exceeded with url: /.well-known/security.txt (Caused by SSLError(SSLCertVerificationError(1, '[SSL: CERTIFICATE_VERIFY_FAILED] certificate verify failed: self-signed certificate (_ssl.c:1131)')))
[2024-01-31T15:28:53.129+0000] {logging_mixin.py:188} INFO - Error retrieving security.txt for 13.53.124.43: HTTPSConnectionPool(host='13.53.124.43', port=443): Max retries exceeded with url: /.well-known/security.txt (Caused by SSLError(SSLCertVerificationError(1, '[SSL: CERTIFICATE_VERIFY_FAILED] certificate verify failed: self-signed certificate (_ssl.c:1131)')))
[2024-01-31T15:28:53.386+0000] {logging_mixin.py:188} INFO - Error retrieving security.txt for 44.201.194.58: HTTPSConnectionPool(host='44.201.194.58', port=443): Max retries exceeded with url: /.well-known/security.txt (Caused by SSLError(SSLCertVerificationError(1, '[SSL: CERTIFICATE_VERIFY_FAILED] certificate verify failed: self-signed certificate (_ssl.c:1131)')))
[2024-01-31T15:28:53.399+0000] {logging_mixin.py:188} INFO - Enrichment step completed.
[2024-01-31T15:28:53.399+0000] {python.py:201} INFO - Done. Returned value was: None
[2024-01-31T15:28:53.409+0000] {taskinstance.py:1138} INFO - Marking task as SUCCESS. dag_id=cvd_automation_pipeline, task_id=enrich_nuclei_data_task, execution_date=20240131T152828, start_date=20240131T152850, end_date=20240131T152853
[2024-01-31T15:28:53.441+0000] {local_task_job_runner.py:234} INFO - Task exited with return code 0
[2024-01-31T15:28:53.454+0000] {taskinstance.py:3280} INFO - 0 downstream tasks scheduled from follow-on schedule check
