[2024-01-31T15:41:11.188+0000] {taskinstance.py:1956} INFO - Dependencies all met for dep_context=non-requeueable deps ti=<TaskInstance: vulnerability_email_notification.process_vulnerability_data manual__2024-01-31T15:41:09.478221+00:00 [queued]>
[2024-01-31T15:41:11.201+0000] {taskinstance.py:1956} INFO - Dependencies all met for dep_context=requeueable deps ti=<TaskInstance: vulnerability_email_notification.process_vulnerability_data manual__2024-01-31T15:41:09.478221+00:00 [queued]>
[2024-01-31T15:41:11.202+0000] {taskinstance.py:2170} INFO - Starting attempt 1 of 1
[2024-01-31T15:41:11.215+0000] {taskinstance.py:2191} INFO - Executing <Task(PythonOperator): process_vulnerability_data> on 2024-01-31 15:41:09.478221+00:00
[2024-01-31T15:41:11.219+0000] {standard_task_runner.py:60} INFO - Started process 17138 to run task
[2024-01-31T15:41:11.221+0000] {standard_task_runner.py:87} INFO - Running: ['***', 'tasks', 'run', 'vulnerability_email_notification', 'process_vulnerability_data', 'manual__2024-01-31T15:41:09.478221+00:00', '--job-id', '48', '--raw', '--subdir', 'DAGS_FOLDER/cvd_mail_and_reschedule.py', '--cfg-path', '/tmp/tmpv0se6zp2']
[2024-01-31T15:41:11.223+0000] {standard_task_runner.py:88} INFO - Job 48: Subtask process_vulnerability_data
[2024-01-31T15:41:11.268+0000] {task_command.py:423} INFO - Running <TaskInstance: vulnerability_email_notification.process_vulnerability_data manual__2024-01-31T15:41:09.478221+00:00 [running]> on host 8d8bbdf320cd
[2024-01-31T15:41:11.376+0000] {taskinstance.py:2480} INFO - Exporting env vars: AIRFLOW_CTX_DAG_OWNER='***' AIRFLOW_CTX_DAG_ID='vulnerability_email_notification' AIRFLOW_CTX_TASK_ID='process_vulnerability_data' AIRFLOW_CTX_EXECUTION_DATE='2024-01-31T15:41:09.478221+00:00' AIRFLOW_CTX_TRY_NUMBER='1' AIRFLOW_CTX_DAG_RUN_ID='manual__2024-01-31T15:41:09.478221+00:00'
[2024-01-31T15:41:11.377+0000] {cvd_mail_and_reschedule.py:62} INFO - SMTP server connecting...
[2024-01-31T15:41:32.395+0000] {cvd_mail_and_reschedule.py:71} ERROR - Failed to connect to SMTP server: [Errno 111] Connection refused
[2024-01-31T15:41:32.396+0000] {python.py:201} INFO - Done. Returned value was: None
[2024-01-31T15:41:32.404+0000] {taskinstance.py:1138} INFO - Marking task as SUCCESS. dag_id=vulnerability_email_notification, task_id=process_vulnerability_data, execution_date=20240131T154109, start_date=20240131T154111, end_date=20240131T154132
[2024-01-31T15:41:32.430+0000] {local_task_job_runner.py:234} INFO - Task exited with return code 0
[2024-01-31T15:41:32.443+0000] {taskinstance.py:3280} INFO - 0 downstream tasks scheduled from follow-on schedule check
