[2024-01-30T18:45:57.143+0000] {taskinstance.py:1956} INFO - Dependencies all met for dep_context=non-requeueable deps ti=<TaskInstance: cvd_automation_pipeline.enrich_nuclei_data_task manual__2024-01-30T18:45:09.855241+00:00 [queued]>
[2024-01-30T18:45:57.151+0000] {taskinstance.py:1956} INFO - Dependencies all met for dep_context=requeueable deps ti=<TaskInstance: cvd_automation_pipeline.enrich_nuclei_data_task manual__2024-01-30T18:45:09.855241+00:00 [queued]>
[2024-01-30T18:45:57.152+0000] {taskinstance.py:2170} INFO - Starting attempt 1 of 1
[2024-01-30T18:45:57.164+0000] {taskinstance.py:2191} INFO - Executing <Task(PythonOperator): enrich_nuclei_data_task> on 2024-01-30 18:45:09.855241+00:00
[2024-01-30T18:45:57.168+0000] {standard_task_runner.py:60} INFO - Started process 1414 to run task
[2024-01-30T18:45:57.169+0000] {standard_task_runner.py:87} INFO - Running: ['***', 'tasks', 'run', 'cvd_automation_pipeline', 'enrich_nuclei_data_task', 'manual__2024-01-30T18:45:09.855241+00:00', '--job-id', '11', '--raw', '--subdir', 'DAGS_FOLDER/cvd_pipeline_1.py', '--cfg-path', '/tmp/tmpr_eorqm7']
[2024-01-30T18:45:57.171+0000] {standard_task_runner.py:88} INFO - Job 11: Subtask enrich_nuclei_data_task
[2024-01-30T18:45:57.203+0000] {task_command.py:423} INFO - Running <TaskInstance: cvd_automation_pipeline.enrich_nuclei_data_task manual__2024-01-30T18:45:09.855241+00:00 [running]> on host 8d8bbdf320cd
[2024-01-30T18:45:57.267+0000] {taskinstance.py:2480} INFO - Exporting env vars: AIRFLOW_CTX_DAG_OWNER='***' AIRFLOW_CTX_DAG_ID='cvd_automation_pipeline' AIRFLOW_CTX_TASK_ID='enrich_nuclei_data_task' AIRFLOW_CTX_EXECUTION_DATE='2024-01-30T18:45:09.855241+00:00' AIRFLOW_CTX_TRY_NUMBER='1' AIRFLOW_CTX_DAG_RUN_ID='manual__2024-01-30T18:45:09.855241+00:00'
[2024-01-30T18:46:19.940+0000] {logging_mixin.py:188} INFO - Error retrieving security.txt for 124.222.233.238: HTTPSConnectionPool(host='124.222.233.238', port=443): Max retries exceeded with url: /.well-known/security.txt (Caused by SSLError(SSLZeroReturnError(6, 'TLS/SSL connection has been closed (EOF) (_ssl.c:1131)')))
[2024-01-30T18:46:20.022+0000] {logging_mixin.py:188} INFO - Error retrieving security.txt for 51.21.131.99: HTTPSConnectionPool(host='51.21.131.99', port=443): Max retries exceeded with url: /.well-known/security.txt (Caused by SSLError(SSLCertVerificationError(1, '[SSL: CERTIFICATE_VERIFY_FAILED] certificate verify failed: self-signed certificate (_ssl.c:1131)')))
[2024-01-30T18:46:20.283+0000] {logging_mixin.py:188} INFO - Error retrieving security.txt for 52.23.211.219: HTTPSConnectionPool(host='52.23.211.219', port=443): Max retries exceeded with url: /.well-known/security.txt (Caused by SSLError(SSLCertVerificationError(1, '[SSL: CERTIFICATE_VERIFY_FAILED] certificate verify failed: self-signed certificate (_ssl.c:1131)')))
[2024-01-30T18:46:20.525+0000] {logging_mixin.py:188} INFO - Error retrieving security.txt for 54.224.146.28: HTTPSConnectionPool(host='54.224.146.28', port=443): Max retries exceeded with url: /.well-known/security.txt (Caused by SSLError(SSLCertVerificationError(1, '[SSL: CERTIFICATE_VERIFY_FAILED] certificate verify failed: self-signed certificate (_ssl.c:1131)')))
[2024-01-30T18:46:20.911+0000] {logging_mixin.py:188} INFO - Error retrieving security.txt for 65.1.100.235: HTTPSConnectionPool(host='65.1.100.235', port=443): Max retries exceeded with url: /.well-known/security.txt (Caused by SSLError(SSLCertVerificationError(1, '[SSL: CERTIFICATE_VERIFY_FAILED] certificate verify failed: self-signed certificate (_ssl.c:1131)')))
[2024-01-30T18:46:20.916+0000] {logging_mixin.py:188} INFO - Enrichment step completed.
[2024-01-30T18:46:20.916+0000] {python.py:201} INFO - Done. Returned value was: None
[2024-01-30T18:46:20.925+0000] {taskinstance.py:1138} INFO - Marking task as SUCCESS. dag_id=cvd_automation_pipeline, task_id=enrich_nuclei_data_task, execution_date=20240130T184509, start_date=20240130T184557, end_date=20240130T184620
[2024-01-30T18:46:20.951+0000] {local_task_job_runner.py:234} INFO - Task exited with return code 0
[2024-01-30T18:46:20.963+0000] {taskinstance.py:3280} INFO - 0 downstream tasks scheduled from follow-on schedule check
