[2024-01-31T15:22:22.190+0000] {taskinstance.py:1956} INFO - Dependencies all met for dep_context=non-requeueable deps ti=<TaskInstance: cvd_automation_pipeline.enrich_nuclei_data_task manual__2024-01-31T15:22:04.982374+00:00 [queued]>
[2024-01-31T15:22:22.199+0000] {taskinstance.py:1956} INFO - Dependencies all met for dep_context=requeueable deps ti=<TaskInstance: cvd_automation_pipeline.enrich_nuclei_data_task manual__2024-01-31T15:22:04.982374+00:00 [queued]>
[2024-01-31T15:22:22.199+0000] {taskinstance.py:2170} INFO - Starting attempt 1 of 1
[2024-01-31T15:22:22.212+0000] {taskinstance.py:2191} INFO - Executing <Task(PythonOperator): enrich_nuclei_data_task> on 2024-01-31 15:22:04.982374+00:00
[2024-01-31T15:22:22.216+0000] {standard_task_runner.py:60} INFO - Started process 15252 to run task
[2024-01-31T15:22:22.218+0000] {standard_task_runner.py:87} INFO - Running: ['***', 'tasks', 'run', 'cvd_automation_pipeline', 'enrich_nuclei_data_task', 'manual__2024-01-31T15:22:04.982374+00:00', '--job-id', '34', '--raw', '--subdir', 'DAGS_FOLDER/cvd_pipeline_1.py', '--cfg-path', '/tmp/tmp1civ2j3o']
[2024-01-31T15:22:22.219+0000] {standard_task_runner.py:88} INFO - Job 34: Subtask enrich_nuclei_data_task
[2024-01-31T15:22:22.255+0000] {task_command.py:423} INFO - Running <TaskInstance: cvd_automation_pipeline.enrich_nuclei_data_task manual__2024-01-31T15:22:04.982374+00:00 [running]> on host 8d8bbdf320cd
[2024-01-31T15:22:22.321+0000] {taskinstance.py:2480} INFO - Exporting env vars: AIRFLOW_CTX_DAG_OWNER='***' AIRFLOW_CTX_DAG_ID='cvd_automation_pipeline' AIRFLOW_CTX_TASK_ID='enrich_nuclei_data_task' AIRFLOW_CTX_EXECUTION_DATE='2024-01-31T15:22:04.982374+00:00' AIRFLOW_CTX_TRY_NUMBER='1' AIRFLOW_CTX_DAG_RUN_ID='manual__2024-01-31T15:22:04.982374+00:00'
[2024-01-31T15:22:22.665+0000] {taskinstance.py:2698} ERROR - Task failed with exception
Traceback (most recent call last):
  File "/home/airflow/.local/lib/python3.8/site-packages/airflow/models/taskinstance.py", line 433, in _execute_task
    result = execute_callable(context=context, **execute_callable_kwargs)
  File "/home/airflow/.local/lib/python3.8/site-packages/airflow/operators/python.py", line 199, in execute
    return_value = self.execute_callable()
  File "/home/airflow/.local/lib/python3.8/site-packages/airflow/operators/python.py", line 216, in execute_callable
    return self.python_callable(*self.op_args, **self.op_kwargs)
  File "/opt/airflow/dags/cvd_pipeline_1.py", line 152, in enrich_nuclei_data
    subprocess.run(cmd, shell=True, check=True)
  File "/usr/local/lib/python3.8/subprocess.py", line 516, in run
    raise CalledProcessError(retcode, process.args,
subprocess.CalledProcessError: Command 'cd /opt/airflow/nuclei-parse-enrich && go run cmd/main.go -i ../data/DIVD-2024-XXXX/2024-01-31-nuclei-results.json -o ../data/DIVD-2024-XXXX/enriched_nuclei_results/output.json' returned non-zero exit status 1.
[2024-01-31T15:22:22.675+0000] {taskinstance.py:1138} INFO - Marking task as FAILED. dag_id=cvd_automation_pipeline, task_id=enrich_nuclei_data_task, execution_date=20240131T152204, start_date=20240131T152222, end_date=20240131T152222
[2024-01-31T15:22:22.687+0000] {standard_task_runner.py:107} ERROR - Failed to execute job 34 for task enrich_nuclei_data_task (Command 'cd /opt/airflow/nuclei-parse-enrich && go run cmd/main.go -i ../data/DIVD-2024-XXXX/2024-01-31-nuclei-results.json -o ../data/DIVD-2024-XXXX/enriched_nuclei_results/output.json' returned non-zero exit status 1.; 15252)
[2024-01-31T15:22:22.713+0000] {local_task_job_runner.py:234} INFO - Task exited with return code 1
[2024-01-31T15:22:22.728+0000] {taskinstance.py:3280} INFO - 0 downstream tasks scheduled from follow-on schedule check
