[2024-01-31T15:30:47.471+0000] {taskinstance.py:1956} INFO - Dependencies all met for dep_context=non-requeueable deps ti=<TaskInstance: cvd_automation_pipeline.enrich_nuclei_data_task manual__2024-01-31T15:30:07.638854+00:00 [queued]>
[2024-01-31T15:30:47.478+0000] {taskinstance.py:1956} INFO - Dependencies all met for dep_context=requeueable deps ti=<TaskInstance: cvd_automation_pipeline.enrich_nuclei_data_task manual__2024-01-31T15:30:07.638854+00:00 [queued]>
[2024-01-31T15:30:47.479+0000] {taskinstance.py:2170} INFO - Starting attempt 1 of 1
[2024-01-31T15:30:47.490+0000] {taskinstance.py:2191} INFO - Executing <Task(PythonOperator): enrich_nuclei_data_task> on 2024-01-31 15:30:07.638854+00:00
[2024-01-31T15:30:47.494+0000] {standard_task_runner.py:60} INFO - Started process 16065 to run task
[2024-01-31T15:30:47.496+0000] {standard_task_runner.py:87} INFO - Running: ['***', 'tasks', 'run', 'cvd_automation_pipeline', 'enrich_nuclei_data_task', 'manual__2024-01-31T15:30:07.638854+00:00', '--job-id', '40', '--raw', '--subdir', 'DAGS_FOLDER/cvd_pipeline_1.py', '--cfg-path', '/tmp/tmp676qbuw4']
[2024-01-31T15:30:47.497+0000] {standard_task_runner.py:88} INFO - Job 40: Subtask enrich_nuclei_data_task
[2024-01-31T15:30:47.531+0000] {task_command.py:423} INFO - Running <TaskInstance: cvd_automation_pipeline.enrich_nuclei_data_task manual__2024-01-31T15:30:07.638854+00:00 [running]> on host 8d8bbdf320cd
[2024-01-31T15:30:47.593+0000] {taskinstance.py:2480} INFO - Exporting env vars: AIRFLOW_CTX_DAG_OWNER='***' AIRFLOW_CTX_DAG_ID='cvd_automation_pipeline' AIRFLOW_CTX_TASK_ID='enrich_nuclei_data_task' AIRFLOW_CTX_EXECUTION_DATE='2024-01-31T15:30:07.638854+00:00' AIRFLOW_CTX_TRY_NUMBER='1' AIRFLOW_CTX_DAG_RUN_ID='manual__2024-01-31T15:30:07.638854+00:00'
[2024-01-31T15:30:49.314+0000] {taskinstance.py:2698} ERROR - Task failed with exception
Traceback (most recent call last):
  File "/home/airflow/.local/lib/python3.8/site-packages/airflow/models/taskinstance.py", line 433, in _execute_task
    result = execute_callable(context=context, **execute_callable_kwargs)
  File "/home/airflow/.local/lib/python3.8/site-packages/airflow/operators/python.py", line 199, in execute
    return_value = self.execute_callable()
  File "/home/airflow/.local/lib/python3.8/site-packages/airflow/operators/python.py", line 216, in execute_callable
    return self.python_callable(*self.op_args, **self.op_kwargs)
  File "/opt/airflow/dags/cvd_pipeline_1.py", line 156, in enrich_nuclei_data
    with open(enriched_output_path, 'r') as file:
FileNotFoundError: [Errno 2] No such file or directory: 'data/DIVD-2024-XXXX/enriched_nuclei_results/enriched_{current_date}.json'
[2024-01-31T15:30:49.324+0000] {taskinstance.py:1138} INFO - Marking task as FAILED. dag_id=cvd_automation_pipeline, task_id=enrich_nuclei_data_task, execution_date=20240131T153007, start_date=20240131T153047, end_date=20240131T153049
[2024-01-31T15:30:49.336+0000] {standard_task_runner.py:107} ERROR - Failed to execute job 40 for task enrich_nuclei_data_task ([Errno 2] No such file or directory: 'data/DIVD-2024-XXXX/enriched_nuclei_results/enriched_{current_date}.json'; 16065)
[2024-01-31T15:30:49.356+0000] {local_task_job_runner.py:234} INFO - Task exited with return code 1
[2024-01-31T15:30:49.372+0000] {taskinstance.py:3280} INFO - 0 downstream tasks scheduled from follow-on schedule check
