[2024-01-31T15:41:11.184+0000] {taskinstance.py:1956} INFO - Dependencies all met for dep_context=non-requeueable deps ti=<TaskInstance: vulnerability_email_notification.trigger_next_dag manual__2024-01-31T15:41:09.478221+00:00 [queued]>
[2024-01-31T15:41:11.195+0000] {taskinstance.py:1956} INFO - Dependencies all met for dep_context=requeueable deps ti=<TaskInstance: vulnerability_email_notification.trigger_next_dag manual__2024-01-31T15:41:09.478221+00:00 [queued]>
[2024-01-31T15:41:11.196+0000] {taskinstance.py:2170} INFO - Starting attempt 1 of 1
[2024-01-31T15:41:11.212+0000] {taskinstance.py:2191} INFO - Executing <Task(TriggerDagRunOperator): trigger_next_dag> on 2024-01-31 15:41:09.478221+00:00
[2024-01-31T15:41:11.217+0000] {standard_task_runner.py:60} INFO - Started process 17137 to run task
[2024-01-31T15:41:11.220+0000] {standard_task_runner.py:87} INFO - Running: ['***', 'tasks', 'run', 'vulnerability_email_notification', 'trigger_next_dag', 'manual__2024-01-31T15:41:09.478221+00:00', '--job-id', '47', '--raw', '--subdir', 'DAGS_FOLDER/cvd_mail_and_reschedule.py', '--cfg-path', '/tmp/tmp_wep5r63']
[2024-01-31T15:41:11.222+0000] {standard_task_runner.py:88} INFO - Job 47: Subtask trigger_next_dag
[2024-01-31T15:41:11.264+0000] {task_command.py:423} INFO - Running <TaskInstance: vulnerability_email_notification.trigger_next_dag manual__2024-01-31T15:41:09.478221+00:00 [running]> on host 8d8bbdf320cd
[2024-01-31T15:41:11.379+0000] {taskinstance.py:2480} INFO - Exporting env vars: AIRFLOW_CTX_DAG_OWNER='***' AIRFLOW_CTX_DAG_ID='vulnerability_email_notification' AIRFLOW_CTX_TASK_ID='trigger_next_dag' AIRFLOW_CTX_EXECUTION_DATE='2024-01-31T15:41:09.478221+00:00' AIRFLOW_CTX_TRY_NUMBER='1' AIRFLOW_CTX_DAG_RUN_ID='manual__2024-01-31T15:41:09.478221+00:00'
[2024-01-31T15:41:11.394+0000] {taskinstance.py:2698} ERROR - Task failed with exception
Traceback (most recent call last):
  File "/home/airflow/.local/lib/python3.8/site-packages/airflow/models/taskinstance.py", line 433, in _execute_task
    result = execute_callable(context=context, **execute_callable_kwargs)
  File "/home/airflow/.local/lib/python3.8/site-packages/airflow/operators/trigger_dagrun.py", line 165, in execute
    dag_run = trigger_dag(
  File "/home/airflow/.local/lib/python3.8/site-packages/airflow/api/common/trigger_dag.py", line 122, in trigger_dag
    raise DagNotFound(f"Dag id {dag_id} not found in DagModel")
airflow.exceptions.DagNotFound: Dag id second_dag_id not found in DagModel
[2024-01-31T15:41:11.398+0000] {taskinstance.py:1138} INFO - Marking task as FAILED. dag_id=vulnerability_email_notification, task_id=trigger_next_dag, execution_date=20240131T154109, start_date=20240131T154111, end_date=20240131T154111
[2024-01-31T15:41:11.411+0000] {standard_task_runner.py:107} ERROR - Failed to execute job 47 for task trigger_next_dag (Dag id second_dag_id not found in DagModel; 17137)
[2024-01-31T15:41:11.432+0000] {local_task_job_runner.py:234} INFO - Task exited with return code 1
[2024-01-31T15:41:11.447+0000] {taskinstance.py:3280} INFO - 0 downstream tasks scheduled from follow-on schedule check
