[2024-01-30T23:49:13.740+0000] {taskinstance.py:1956} INFO - Dependencies all met for dep_context=non-requeueable deps ti=<TaskInstance: vulnerability_email_notification.process_vulnerability_data manual__2024-01-30T23:49:12.730763+00:00 [queued]>
[2024-01-30T23:49:13.752+0000] {taskinstance.py:1956} INFO - Dependencies all met for dep_context=requeueable deps ti=<TaskInstance: vulnerability_email_notification.process_vulnerability_data manual__2024-01-30T23:49:12.730763+00:00 [queued]>
[2024-01-30T23:49:13.754+0000] {taskinstance.py:2170} INFO - Starting attempt 1 of 1
[2024-01-30T23:49:13.775+0000] {taskinstance.py:2191} INFO - Executing <Task(PythonOperator): process_vulnerability_data> on 2024-01-30 23:49:12.730763+00:00
[2024-01-30T23:49:13.783+0000] {standard_task_runner.py:60} INFO - Started process 7335 to run task
[2024-01-30T23:49:13.785+0000] {standard_task_runner.py:87} INFO - Running: ['***', 'tasks', 'run', 'vulnerability_email_notification', 'process_vulnerability_data', 'manual__2024-01-30T23:49:12.730763+00:00', '--job-id', '23', '--raw', '--subdir', 'DAGS_FOLDER/cvd_mail_and_reschedule.py', '--cfg-path', '/tmp/tmp95kz4cue']
[2024-01-30T23:49:13.787+0000] {standard_task_runner.py:88} INFO - Job 23: Subtask process_vulnerability_data
[2024-01-30T23:49:13.846+0000] {task_command.py:423} INFO - Running <TaskInstance: vulnerability_email_notification.process_vulnerability_data manual__2024-01-30T23:49:12.730763+00:00 [running]> on host 8d8bbdf320cd
[2024-01-30T23:49:13.946+0000] {taskinstance.py:2480} INFO - Exporting env vars: AIRFLOW_CTX_DAG_OWNER='***' AIRFLOW_CTX_DAG_ID='vulnerability_email_notification' AIRFLOW_CTX_TASK_ID='process_vulnerability_data' AIRFLOW_CTX_EXECUTION_DATE='2024-01-30T23:49:12.730763+00:00' AIRFLOW_CTX_TRY_NUMBER='1' AIRFLOW_CTX_DAG_RUN_ID='manual__2024-01-30T23:49:12.730763+00:00'
[2024-01-30T23:49:13.948+0000] {cvd_mail_and_reschedule.py:61} INFO - SMTP server connecting...
[2024-01-30T23:51:24.802+0000] {cvd_mail_and_reschedule.py:70} ERROR - Failed to connect to SMTP server: [Errno 110] Connection timed out
[2024-01-30T23:51:24.803+0000] {python.py:201} INFO - Done. Returned value was: None
[2024-01-30T23:51:24.819+0000] {taskinstance.py:1138} INFO - Marking task as SUCCESS. dag_id=vulnerability_email_notification, task_id=process_vulnerability_data, execution_date=20240130T234912, start_date=20240130T234913, end_date=20240130T235124
[2024-01-30T23:51:24.848+0000] {local_task_job_runner.py:234} INFO - Task exited with return code 0
[2024-01-30T23:51:24.870+0000] {taskinstance.py:3280} INFO - 0 downstream tasks scheduled from follow-on schedule check
