[2024-01-31T00:03:46.002+0000] {taskinstance.py:1956} INFO - Dependencies all met for dep_context=non-requeueable deps ti=<TaskInstance: vulnerability_email_notification.process_vulnerability_data manual__2024-01-31T00:03:44.739174+00:00 [queued]>
[2024-01-31T00:03:46.015+0000] {taskinstance.py:1956} INFO - Dependencies all met for dep_context=requeueable deps ti=<TaskInstance: vulnerability_email_notification.process_vulnerability_data manual__2024-01-31T00:03:44.739174+00:00 [queued]>
[2024-01-31T00:03:46.016+0000] {taskinstance.py:2170} INFO - Starting attempt 1 of 1
[2024-01-31T00:03:46.035+0000] {taskinstance.py:2191} INFO - Executing <Task(PythonOperator): process_vulnerability_data> on 2024-01-31 00:03:44.739174+00:00
[2024-01-31T00:03:46.042+0000] {standard_task_runner.py:60} INFO - Started process 8071 to run task
[2024-01-31T00:03:46.045+0000] {standard_task_runner.py:87} INFO - Running: ['***', 'tasks', 'run', 'vulnerability_email_notification', 'process_vulnerability_data', 'manual__2024-01-31T00:03:44.739174+00:00', '--job-id', '24', '--raw', '--subdir', 'DAGS_FOLDER/cvd_mail_and_reschedule.py', '--cfg-path', '/tmp/tmp5fd4a9r5']
[2024-01-31T00:03:46.048+0000] {standard_task_runner.py:88} INFO - Job 24: Subtask process_vulnerability_data
[2024-01-31T00:03:46.108+0000] {task_command.py:423} INFO - Running <TaskInstance: vulnerability_email_notification.process_vulnerability_data manual__2024-01-31T00:03:44.739174+00:00 [running]> on host 8d8bbdf320cd
[2024-01-31T00:03:46.217+0000] {taskinstance.py:2480} INFO - Exporting env vars: AIRFLOW_CTX_DAG_OWNER='***' AIRFLOW_CTX_DAG_ID='vulnerability_email_notification' AIRFLOW_CTX_TASK_ID='process_vulnerability_data' AIRFLOW_CTX_EXECUTION_DATE='2024-01-31T00:03:44.739174+00:00' AIRFLOW_CTX_TRY_NUMBER='1' AIRFLOW_CTX_DAG_RUN_ID='manual__2024-01-31T00:03:44.739174+00:00'
[2024-01-31T00:03:46.219+0000] {cvd_mail_and_reschedule.py:61} INFO - SMTP server connecting...
[2024-01-31T00:04:06.213+0000] {local_task_job_runner.py:302} WARNING - State of this instance has been externally set to failed. Terminating instance.
[2024-01-31T00:04:06.216+0000] {process_utils.py:131} INFO - Sending 15 to group 8071. PIDs of all processes in the group: [8071]
[2024-01-31T00:04:06.217+0000] {process_utils.py:86} INFO - Sending the signal 15 to group 8071
[2024-01-31T00:04:06.217+0000] {taskinstance.py:2450} ERROR - Received SIGTERM. Terminating subprocesses.
[2024-01-31T00:04:06.218+0000] {cvd_mail_and_reschedule.py:70} ERROR - Failed to connect to SMTP server: Task received SIGTERM signal
[2024-01-31T00:04:06.219+0000] {python.py:201} INFO - Done. Returned value was: None
[2024-01-31T00:04:06.232+0000] {taskinstance.py:1138} INFO - Marking task as SUCCESS. dag_id=vulnerability_email_notification, task_id=process_vulnerability_data, execution_date=20240131T000344, start_date=20240131T000346, end_date=20240131T000406
[2024-01-31T00:04:06.270+0000] {process_utils.py:79} INFO - Process psutil.Process(pid=8071, status='terminated', exitcode=0, started='00:03:45') (8071) terminated with exit code 0
